data/input.txt
AAPL 1 BUY LIMIT 100 10
AAPL 2 BUY LIMIT 101 5
AAPL 3 SELL LIMIT 105 20
AAPL 4 SELL LIMIT 101 7
AAPL 5 SELL LIMIT 100 10
AAPL CANCEL 3
AAPL CANCEL 999
MSFT 6 SELL LIMIT 250 10
MSFT 7 BUY LIMIT 249 5
MSFT 8 BUY LIMIT 250 12
AAPL 9 BUY LIMIT 99 20
AAPL 10 SELL LIMIT 99 5
AAPL 11 SELL LIMIT 99 10
AAPL CANCEL 9
GOOG 12 BUY LIMIT 1500 3
GOOG 13 SELL LIMIT 1499 1
GOOG 14 SELL LIMIT 1500 5
GOOG CANCEL 14
GOOG CANCEL 12
